Workbook

Sheet Start Here
B2: 9-Box Talent Assessment - Business Unit Workbook
B3: Vanderbilt University · People, Culture & Belonging · M4-E1 · FY27 · one workbook per business unit
B5: WHAT THIS WORKBOOK DOES
B6: It automates the whole unit exercise: criterion totals, the 16/25 critical call and the ±2 borderline second-discussion flag, the Ability/Aspiration/Engagement → Potential rule, the box placement, the SBJA gap math, the live 9-box grid, the QA checks, and the readout dashboard. You type evidence and judgments in the yellow cells; every grey '(auto)' column computes itself. Formula cells are locked so they can't be typed over (Review → Unprotect Sheet removes the guard; there is no password).
B8: HOW TO RUN YOUR UNIT
B9: 1 · Setup | C9: Enter the unit, EC, calibration chair, facilitator, calibration date, wave, and your team list. The thresholds and box labels are the program design locked at the Sept 11 gate - change them only with the program team.
B10: 2 · 1. Role Scoring | C10: List every M4-E1 role and score the five criteria live in the 75-minute session (hover each score column's header for the prompt and anchors). The total, the borderline flag and the CRITICAL? call compute automatically. Record the one-sentence rationale - the list must be auditable across all 39 units.
B11: 3 · 2. Assessment | C11: One row per incumbent. Enter reviews on record, career-conversation date, performance evidence, the Performance rating (1-3) and the A/A/E reads. Potential and the proposed box appear automatically.
B12: 4 · 3. Skills (SBJA) | C12: Critical-role incumbents only: list the role's SBJA skills, the required level, and the person's current level. Gaps and the % at/above flow back to the Assessment tab and become the development plan.
B13: 5 · Calibrate | C13: In the session the manager presents 2 minutes, the panel challenges, the one-up leader decides. Record the Panel decision (accept / override / support pathway / defer), any override rationale and dissent, and - critical roles only - readiness, retention risk (always paired with an action) and coverage.
B14: 6 · Read out | C14: The 9-Box Grid and Dashboard update live. Your unit is complete when the Dashboard shows all four outputs green and zero QA items. 'Export (flat)' is the sheet the program team collects for the enterprise dataset.
B16: LEGEND
B17: You type here | C17: Computed - locked, don't type | D17: ⚠ QA - fix it | E17: Critical / good | F17: Needs attention | G17: Risk / red
B19: HOW ONE PERSON LANDS IN A BOX
B20: Performance evidence sets the row. The Ability, Aspiration, Engagement read sets the column. The SBJA skills check backs both and hands the manager a ready-made development plan. Row meets column - that is the box - and the calibration panel confirms it. Everything else in this workbook exists only to keep that simple move honest.
B22: WHAT THIS IS NOT
B23: Not successor slating, not a promotion list, not a layoff exercise, not performance management, and nothing below M4. Managers never share a grid label - employees get a real conversation about strengths, aspirations, readiness, development priorities and opportunities. Choosing deep expertise over broader scope is a valid and valued path. This data is never used for compensation, layoffs, discipline, or automated employment decisions.
B25: THE FIVE CRITICAL-ROLE CRITERIA (anchors also sit in the score-column header notes)
B26: Criterion & prompt | C26: 1 (low) | F26: 3 (moderate) | H26: 5 (high)
B27: 1 Impact - what breaks in 30-90 days if this seat fails or empties? | C27: Work absorbed by others with little disruption. | F27: A key function noticeably disrupted; workarounds hold. | H27: A core function or strategic priority visibly impaired within weeks.
B28: 2 Performance variability - how different are outcomes between an average and a great person? | C28: Output largely fixed by process. | F28: A great performer meaningfully improves quality, cost, or speed. | H28: Outcomes swing dramatically on the incumbent's judgment, expertise, or relationships.
B29: 3 Skill scarcity - how rare is the expertise or undocumented institutional knowledge? | C29: Skills common in the market; knowledge documented. | F29: Skills take 1-2 years; some knowledge undocumented. | H29: Expertise rare or takes years; heavy undocumented institutional knowledge.
B30: 4 Internal bench (REVERSE-scored) - could anyone inside credibly cover this role today? | C30: Several people could credibly cover it today. | F30: One plausible person, with real development gaps. | H30: No plausible internal coverage.
B31: 5 Market & vacancy risk - how hard is an external search; how likely a vacancy in 3 years? | C31: Fast, inexpensive external hire; stable incumbent. | F31: A 3-6 month search, or a moderate chance of vacancy. | H31: A 6-12+ month costly search, and vacancy plausible within 1-3 years.
B32: 16 of 25 is the initial threshold - a design choice tested in the pilot. Scores within 2 points get a second discussion. Not seniority, not the incumbent: score the seat with a stranger in it. Don't assume all roles are critical - many senior seats are important, visible, and refillable.
B34: CALIBRATION RULES - QUICK REFERENCE
B35: Performance (row) | C35: 3 Exceeds · 2 Meets · 1 Below, over the last 12-18 months. Reviews on record first (at most two), then results and two specific examples. No review = structured retrospective, flagged, one extra probe.
B36: Potential (column) | C36: Ability, Aspiration, Engagement - each High/Med/Low. All three High = High; any Low = Low. Ability is demonstrated learning agility. Aspiration only from a documented career conversation. Engagement is observable behavior and stated intent - never location, caregiving, or willingness to relocate.
B37: Decision | C37: Manager presents 2 minutes, the panel challenges, the one-up leader decides. Overrides and dissent are documented. Active performance process = support pathway, no label. Pay, slating and improvement topics get parked.
B38: Flags | C38: Retention risk: critical roles and calibrated regrettable-loss risk only - confidential, evidence-based, always paired with an action. Critical incumbents add readiness (Now / 1-2 / 3+ yrs) and coverage (Red / Yellow / Green). Under 6 months in role defers.
B39: Guardrails | C39: No target distribution - concentrated results trigger an evidence and fairness review, never a curve. Placements refresh every 6-12 months; a box is a snapshot, not a verdict. Exceptional craft with no appetite for broader scope is High Professional, a valued destination.
B41: WORKED EXAMPLE - People Operations (from the program document; reference only, the entry tabs start clean)
B42: Real SBJA roles, fictional people and scores. Enter these on the entry tabs and the workbook reproduces every result below - a useful self-test and training aid.
B43: Role (level) | C43: Impact | D43: Perf var | E43: Scarcity | F43: Bench | G43: Mkt/vac | H43: Total | I43: Critical?
B44: People Operations Executive (E1) | C44: 5 | D44: 4 | E44: 4 | F44: 4 | G44: 4 | H44: 21 | I44: YES
B45: Total Rewards Lead (M5) | C45: 4 | D45: 3 | E45: 4 | F45: 3 | G45: 4 | H45: 18 | I45: YES
B46: Consulting Lead (M5) | C46: 3 | D46: 4 | E46: 3 | F46: 2 | G46: 3 | H46: 15 | I46: No (±2 - held at No after the 2nd discussion)
B47: Learning & Development Lead (M4) | C47: 3 | D47: 3 | E47: 3 | F47: 2 | G47: 3 | H47: 14 | I47: No
B48: Payroll Lead (M4) | C48: 4 | D48: 2 | E48: 2 | F48: 2 | G48: 2 | H48: 12 | I48: No
B49: Payroll touches every employee yet scored 12: documented processes, refillable seat. Total Rewards scored critical: hot market, scarce expertise, thin bench. Criticality follows risk and replaceability, not visibility.
...

Sheet Setup
A1: Setup & Program Settings
A2: Yellow cells are yours to fill. Everything else is set by the program design locked at the Sept 11 gate.
A3: UNIT INFORMATION
A4: Business Unit
A5: Engagement Consultant (EC)
A6: Calibration chair (one-up leader)
A7: Facilitator
A8: Calibration session date
A9: Wave
A11: PROGRAM SETTINGS (locked at the Sept 11 gate - change only with the program team)
A12: Critical-role threshold (out of 25) | B12: 16
A13: Borderline band (totals closer than this to the threshold get a mandatory 2nd discussion) | B13: 2
A14: Concentration review trigger (share of placements in the High-potential top boxes) | B14: 0.4
A15: Career-conversation window (days) | B15: 365
A17: TEAMS / SUB-UNITS (feeds the Team dropdown on the entry tabs; optional)
A34: 9-BOX LABELS (row = Performance, column = Potential; labels must stay unique)
B35: Performance ↓ / Potential → | C35: Low | D35: Medium | E35: High
B36: 3 - Exceeds | C36: High Professional | D36: Emerging Talent | E36: High Potential
B37: 2 - Meets | C37: Solid Professional | D37: Core Performer | E37: Solid Performer, Strong Potential
B38: 1 - Below | C38: Action Required | D38: Inconsistent Performer | E38: Rough Diamond
A40: Label defaults follow the program document's worked example: High Potential, Emerging Talent, High Professional, and 'Solid Performer, Strong Potential' are the document's own terms; the rest are standard 9-box names and may be renamed here.

Sheet 1. Role Scoring
A1: Step 1 - Score the Roles
A2: Score every M4-E1 role on the five anchored 1-5 scales (hover a scored column's header for the prompt and anchors). Higher always means more critical; Internal bench is reverse-scored (no bench = 5). Totals, the borderline second-discussion flag and the CRITICAL? call compute automatically. Every score needs a one-sentence rationale. Score the seat with a stranger in it - not the incumbent.
A5: Role ID (auto) | B5: Role title | C5: Level | D5: Team | E5: VC/CoS call-out? | F5: 1 Impact (1-5) | G5: 2 Perf variability (1-5) | H5: 3 Skill scarcity (1-5) | I5: 4 Internal bench (reverse) (1-5) | J5: 5 Market & vacancy risk (1-5) | K5: Total /25 (auto) | L5: Preliminary result (auto) | M5: 2nd discussion held? | N5: 2nd discussion outcome | O5: CRITICAL? (auto) | P5: Rationale (one sentence) | Q5: QA (auto)
A6: =IF($B6="","","R"&TEXT(ROW()-5,"000")) | K6: =IF($B6="","",IF(COUNT($F6:$J6)<5,"",SUM($F6:$J6))) | L6: =IF($B6="","",IF(COUNT($F6:$J6)<5,"Scores incomplete",IF($K6>=Setup!$B$12,"Critical","Not critical")&IF(ABS($K6-Setup!$B$12)<Setup!$B$13," (borderline - 2nd discussion)",""))) | O6: =IF($B6="","",IF(COUNT($F6:$J6)<5,"Pending scores",IF(ABS($K6-Setup!$B$12)<Setup!$B$13,IF($N6="Confirmed critical","YES",IF($N6="Held at Not critical","No","Pending 2nd discussion")),IF($K6>=Setup!$B$12,"YES","No")))) | Q6: =IF($B6="","",IF(COUNT($F6:$J6)<5,"⚠ Scores incomplete",_xlfn.TEXTJOIN(" · ",TRUE(),IF($P6="","⚠ Rationale missing",""),IF(AND(ABS($K6-Setup!$B$12)<Setup!$B$13,$M6<>"Yes"),"⚠ 2nd discussion required",""),IF(AND(ABS($K6-Setup!$B$12)<Setup!$B$13,$N6=""),"⚠ Outcome not recorded",""))))
A7: =IF($B7="","","R"&TEXT(ROW()-5,"000")) | K7: =IF($B7="","",IF(COUNT($F7:$J7)<5,"",SUM($F7:$J7))) | L7: =IF($B7="","",IF(COUNT($F7:$J7)<5,"Scores incomplete",IF($K7>=Setup!$B$12,"Critical","Not critical")&IF(ABS($K7-Setup!$B$12)<Setup!$B$13," (borderline - 2nd discussion)",""))) | O7: =IF($B7="","",IF(COUNT($F7:$J7)<5,"Pending scores",IF(ABS($K7-Setup!$B$12)<Setup!$B$13,IF($N7="Confirmed critical","YES",IF($N7="Held at Not critical","No","Pending 2nd discussion")),IF($K7>=Setup!$B$12,"YES","No")))) | Q7: =IF($B7="","",IF(COUNT($F7:$J7)<5,"⚠ Scores incomplete",_xlfn.TEXTJOIN(" · ",TRUE(),IF($P7="","⚠ Rationale missing",""),IF(AND(ABS($K7-Setup!$B$12)<Setup!$B$13,$M7<>"Yes"),"⚠ 2nd discussion required",""),IF(AND(ABS($K7-Setup!$B$12)<Setup!$B$13,$N7=""),"⚠ Outcome not recorded",""))))
A8: =IF($B8="","","R"&TEXT(ROW()-5,"000")) | K8: =IF($B8="","",IF(COUNT($F8:$J8)<5,"",SUM($F8:$J8))) | L8: =IF($B8="","",IF(COUNT($F8:$J8)<5,"Scores incomplete",IF($K8>=Setup!$B$12,"Critical","Not critical")&IF(ABS($K8-Setup!$B$12)<Setup!$B$13," (borderline - 2nd discussion)",""))) | O8: =IF($B8="","",IF(COUNT($F8:$J8)<5,"Pending scores",IF(ABS($K8-Setup!$B$12)<Setup!$B$13,IF($N8="Confirmed critical","YES",IF($N8="Held at Not critical","No","Pending 2nd discussion")),IF($K8>=Setup!$B$12,"YES","No")))) | Q8: =IF($B8="","",IF(COUNT($F8:$J8)<5,"⚠ Scores incomplete",_xlfn.TEXTJOIN(" · ",TRUE(),IF($P8="","⚠ Rationale missing",""),IF(AND(ABS($K8-Setup!$B$12)<Setup!$B$13,$M8<>"Yes"),"⚠ 2nd discussion required",""),IF(AND(ABS($K8-Setup!$B$12)<Setup!$B$13,$N8=""),"⚠ Outcome not recorded",""))))
A9: =IF($B9="","","R"&TEXT(ROW()-5,"000")) | K9: =IF($B9="","",IF(COUNT($F9:$J9)<5,"",SUM($F9:$J9))) | L9: =IF($B9="","",IF(COUNT($F9:$J9)<5,"Scores incomplete",IF($K9>=Setup!$B$12,"Critical","Not critical")&IF(ABS($K9-Setup!$B$12)<Setup!$B$13," (borderline - 2nd discussion)",""))) | O9: =IF($B9="","",IF(COUNT($F9:$J9)<5,"Pending scores",IF(ABS($K9-Setup!$B$12)<Setup!$B$13,IF($N9="Confirmed critical","YES",IF($N9="Held at Not critical","No","Pending 2nd discussion")),IF($K9>=Setup!$B$12,"YES","No")))) | Q9: =IF($B9="","",IF(COUNT($F9:$J9)<5,"⚠ Scores incomplete",_xlfn.TEXTJOIN(" · ",TRUE(),IF($P9="","⚠ Rationale missing",""),IF(AND(ABS($K9-Setup!$B$12)<Setup!$B$13,$M9<>"Yes"),"⚠ 2nd discussion required",""),IF(AND(ABS($K9-Setup!$B$12)<Setup!$B$13,$N9=""),"⚠ Outcome not recorded",""))))
A10: =IF($B10="","","R"&TEXT(ROW()-5,"000")) | K10: =IF($B10="","",IF(COUNT($F10:$J10)<5,"",SUM($F10:$J10))) | L10: =IF($B10="","",IF(COUNT($F10:$J10)<5,"Scores incomplete",IF($K10>=Setup!$B$12,"Critical","Not critical")&IF(ABS($K10-Setup!$B$12)<Setup!$B$13," (borderline - 2nd discussion)",""))) | O10: =IF($B10="","",IF(COUNT($F10:$J10)<5,"Pending scores",IF(ABS($K10-Setup!$B$12)<Setup!$B$13,IF($N10="Confirmed critical","YES",IF($N10="Held at Not critical","No","Pending 2nd discussion")),IF($K10>=Setup!$B$12,"YES","No")))) | Q10: =IF($B10="","",IF(COUNT($F10:$J10)<5,"⚠ Scores incomplete",_xlfn.TEXTJOIN(" · ",TRUE(),IF($P10="","⚠ Rationale missing",""),IF(AND(ABS($K10-Setup!$B$12)<Setup!$B$13,$M10<>"Yes"),"⚠ 2nd discussion required",""),IF(AND(ABS($K10-Setup!$B$12)<Setup!$B$13,$N10=""),"⚠ Outcome not recorded",""))))
A11: =IF($B11="","","R"&TEXT(ROW()-5,"000")) | K11: =IF($B11="","",IF(COUNT($F11:$J11)<5,"",SUM($F11:$J11))) | L11: =IF($B11="","",IF(COUNT($F11:$J11)<5,"Scores incomplete",IF($K11>=Setup!$B$12,"Critical","Not critical")&IF(ABS($K11-Setup!$B$12)<Setup!$B$13," (borderline - 2nd discussion)",""))) | O11: =IF($B11="","",IF(COUNT($F11:$J11)<5,"Pending scores",IF(ABS($K11-Setup!$B$12)<Setup!$B$13,IF($N11="Confirmed critical","YES",IF($N11="Held at Not critical","No","Pending 2nd discussion")),IF($K11>=Setup!$B$12,"YES","No")))) | Q11: =IF($B11="","",IF(COUNT($F11:$J11)<5,"⚠ Scores incomplete",_xlfn.TEXTJOIN(" · ",TRUE(),IF($P11="","⚠ Rationale missing",""),IF(AND(ABS($K11-Setup!$B$12)<Setup!$B$13,$M11<>"Yes"),"⚠ 2nd discussion required",""),IF(AND(ABS($K11-Setup!$B$12)<Setup!$B$13,$N11=""),"⚠ Outcome not recorded",""))))
A12: =IF($B12="","","R"&TEXT(ROW()-5,"000")) | K12: =IF($B12="","",IF(COUNT($F12:$J12)<5,"",SUM($F12:$J12))) | L12: =IF($B12="","",IF(COUNT($F12:$J12)<5,"Scores incomplete",IF($K12>=Setup!$B$12,"Critical","Not critical")&IF(ABS($K12-Setup!$B$12)<Setup!$B$13," (borderline - 2nd discussion)",""))) | O12: =IF($B12="","",IF(COUNT($F12:$J12)<5,"Pending scores",IF(ABS($K12-Setup!$B$12)<Setup!$B$13,IF($N12="Confirmed critical","YES",IF($N12="Held at Not critical","No","Pending 2nd discussion")),IF($K12>=Setup!$B$12,"YES","No")))) | Q12: =IF($B12="","",IF(COUNT($F12:$J12)<5,"⚠ Scores incomplete",_xlfn.TEXTJOIN(" · ",TRUE(),IF($P12="","⚠ Rationale missing",""),IF(AND(ABS($K12-Setup!$B$12)<Setup!$B$13,$M12<>"Yes"),"⚠ 2nd discussion required",""),IF(AND(ABS($K12-Setup!$B$12)<Setup!$B$13,$N12=""),"⚠ Outcome not recorded",""))))
A13: =IF($B13="","","R"&TEXT(ROW()-5,"000")) | K13: =IF($B13="","",IF(COUNT($F13:$J13)<5,"",SUM($F13:$J13))) | L13: =IF($B13="","",IF(COUNT($F13:$J13)<5,"Scores incomplete",IF($K13>=Setup!$B$12,"Critical","Not critical")&IF(ABS($K13-Setup!$B$12)<Setup!$B$13," (borderline - 2nd discussion)",""))) | O13: =IF($B13="","",IF(COUNT($F13:$J13)<5,"Pending scores",IF(ABS($K13-Setup!$B$12)<Setup!$B$13,IF($N13="Confirmed critical","YES",IF($N13="Held at Not critical","No","Pending 2nd discussion")),IF($K13>=Setup!$B$12,"YES","No")))) | Q13: =IF($B13="","",IF(COUNT($F13:$J13)<5,"⚠ Scores incomplete",_xlfn.TEXTJOIN(" · ",TRUE(),IF($P13="","⚠ Rationale missing",""),IF(AND(ABS($K13-Setup!$B$12)<Setup!$B$13,$M13<>"Yes"),"⚠ 2nd discussion required",""),IF(AND(ABS($K13-Setup!$B$12)<Setup!$B$13,$N13=""),"⚠ Outcome not recorded",""))))
A14: =IF($B14="","","R"&TEXT(ROW()-5,"000")) | K14: =IF($B14="","",IF(COUNT($F14:$J14)<5,"",SUM($F14:$J14))) | L14: =IF($B14="","",IF(COUNT($F14:$J14)<5,"Scores incomplete",IF($K14>=Setup!$B$12,"Critical","Not critical")&IF(ABS($K14-Setup!$B$12)<Setup!$B$13," (borderline - 2nd discussion)",""))) | O14: =IF($B14="","",IF(COUNT($F14:$J14)<5,"Pending scores",IF(ABS($K14-Setup!$B$12)<Setup!$B$13,IF($N14="Confirmed critical","YES",IF($N14="Held at Not critical","No","Pending 2nd discussion")),IF($K14>=Setup!$B$12,"YES","No")))) | Q14: =IF($B14="","",IF(COUNT($F14:$J14)<5,"⚠ Scores incomplete",_xlfn.TEXTJOIN(" · ",TRUE(),IF($P14="","⚠ Rationale missing",""),IF(AND(ABS($K14-Setup!$B$12)<Setup!$B$13,$M14<>"Yes"),"⚠ 2nd discussion required",""),IF(AND(ABS($K14-Setup!$B$12)<Setup!$B$13,$N14=""),"⚠ Outcome not recorded",""))))
A15: =IF($B15="","","R"&TEXT(ROW()-5,"000")) | K15: =IF($B15="","",IF(COUNT($F15:$J15)<5,"",SUM($F15:$J15))) | L15: =IF($B15="","",IF(COUNT($F15:$J15)<5,"Scores incomplete",IF($K15>=Setup!$B$12,"Critical","Not critical")&IF(ABS($K15-Setup!$B$12)<Setup!$B$13," (borderline - 2nd discussion)",""))) | O15: =IF($B15="","",IF(COUNT($F15:$J15)<5,"Pending scores",IF(ABS($K15-Setup!$B$12)<Setup!$B$13,IF($N15="Confirmed critical","YES",IF($N15="Held at Not critical","No","Pending 2nd discussion")),IF($K15>=Setup!$B$12,"YES","No")))) | Q15: =IF($B15="","",IF(COUNT($F15:$J15)<5,"⚠ Scores incomplete",_xlfn.TEXTJOIN(" · ",TRUE(),IF($P15="","⚠ Rationale missing",""),IF(AND(ABS($K15-Setup!$B$12)<Setup!$B$13,$M15<>"Yes"),"⚠ 2nd discussion required",""),IF(AND(ABS($K15-Setup!$B$12)<Setup!$B$13,$N15=""),"⚠ Outcome not recorded",""))))
A16: =IF($B16="","","R"&TEXT(ROW()-5,"000")) | K16: =IF($B16="","",IF(COUNT($F16:$J16)<5,"",SUM($F16:$J16))) | L16: =IF($B16="","",IF(COUNT($F16:$J16)<5,"Scores incomplete",IF($K16>=Setup!$B$12,"Critical","Not critical")&IF(ABS($K16-Setup!$B$12)<Setup!$B$13," (borderline - 2nd discussion)",""))) | O16: =IF($B16="","",IF(COUNT($F16:$J16)<5,"Pending scores",IF(ABS($K16-Setup!$B$12)<Setup!$B$13,IF($N16="Confirmed critical","YES",IF($N16="Held at Not critical","No","Pending 2nd discussion")),IF($K16>=Setup!$B$12,"YES","No")))) | Q16: =IF($B16="","",IF(COUNT($F16:$J16)<5,"⚠ Scores incomplete",_xlfn.TEXTJOIN(" · ",TRUE(),IF($P16="","⚠ Rationale missing",""),IF(AND(ABS($K16-Setup!$B$12)<Setup!$B$13,$M16<>"Yes"),"⚠ 2nd discussion required",""),IF(AND(ABS($K16-Setup!$B$12)<Setup!$B$13,$N16=""),"⚠ Outcome not recorded",""))))
A17: =IF($B17="","","R"&TEXT(ROW()-5,"000")) | K17: =IF($B17="","",IF(COUNT($F17:$J17)<5,"",SUM($F17:$J17))) | L17: =IF($B17="","",IF(COUNT($F17:$J17)<5,"Scores incomplete",IF($K17>=Setup!$B$12,"Critical","Not critical")&IF(ABS($K17-Setup!$B$12)<Setup!$B$13," (borderline - 2nd discussion)",""))) | O17: =IF($B17="","",IF(COUNT($F17:$J17)<5,"Pending scores",IF(ABS($K17-Setup!$B$12)<Setup!$B$13,IF($N17="Confirmed critical","YES",IF($N17="Held at Not critical","No","Pending 2nd discussion")),IF($K17>=Setup!$B$12,"YES","No")))) | Q17: =IF($B17="","",IF(COUNT($F17:$J17)<5,"⚠ Scores incomplete",_xlfn.TEXTJOIN(" · ",TRUE(),IF($P17="","⚠ Rationale missing",""),IF(AND(ABS($K17-Setup!$B$12)<Setup!$B$13,$M17<>"Yes"),"⚠ 2nd discussion required",""),IF(AND(ABS($K17-Setup!$B$12)<Setup!$B$13,$N17=""),"⚠ Outcome not recorded",""))))
... A255: =IF($B255="","","R"&TEXT(ROW()-5,"000")) | K255: =IF($B255="","",IF(COUNT($F255:$J255)<5,"",SUM($F255:$J255))) | L255: =IF($B255="","",IF(COUNT($F255:$J255)<5,"Scores incomplete",IF($K255>=Setup!$B$12,"Critical","Not critical")&IF(ABS($K255-Setup!$B$12)<Setup!$B$13," (borderline - 2nd discussion)",""))) | O255: =IF($B255="","",IF(COUNT($F255:$J255)<5,"Pending scores",IF(ABS($K255-Setup!$B$12)<Setup!$B$13,IF($N255="Confirmed critical","YES",IF($N255="Held at Not critical","No","Pending 2nd discussion")),IF($K255>=Setup!$B$12,"YES","No")))) | Q255: =IF($B255="","",IF(COUNT($F255:$J255)<5,"⚠ Scores incomplete",_xlfn.TEXTJOIN(" · ",TRUE(),IF($P255="","⚠ Rationale missing",""),IF(AND(ABS($K255-Setup!$B$12)<Setup!$B$13,$M255<>"Yes"),"⚠ 2nd discussion required",""),IF(AND(ABS($K255-Setup!$B$12)<Setup!$B$13,$N255=""),"⚠ Outcome not recorded",""))))

Sheet 2. Assessment
A1: Step 2 & 3 - Assess and Calibrate
A2: One row per M4-E1 incumbent. Enter the evidence, the Performance rating (1-3) and the Ability / Aspiration / Engagement reads: Potential and the proposed box compute automatically (all three High = High; any Low = Low). In calibration the manager presents, the panel challenges, the one-up leader decides - record the panel decision, any override with its rationale, and (critical roles only) readiness, retention risk and coverage. Aspiration comes only from a documented career conversation. Managers never share a grid label.
A5: Person ID (auto) | B5: Name | C5: Role (pick from Step 1) | D5: Level (auto) | E5: Team (auto) | F5: Critical role? (auto) | G5: Assessing manager | H5: Months in role | I5: Active performance process? | J5: Reviews on record (0-2) | K5: Career conversation date | L5: Conversation status (auto) | M5: Performance (1-3) | N5: Performance evidence (results, KPIs, 2 examples) | O5: Evidence basis (auto) | P5: Ability (H/M/L) | Q5: Aspiration (H/M/L) | R5: Engagement (H/M/L) | S5: Potential (auto) | T5: Proposed box (auto) | U5: SBJA skills at/above (auto) | V5: SBJA gaps (auto) | W5: Panel decision | X5: Override placement | Y5: Final box (auto) | Z5: Override / dissent record | AA5: Readiness (critical only) | AB5: Retention risk? (critical only) | AC5: Risk evidence & action (required if risk = Yes) | AD5: Coverage (critical only) | AE5: Flags status (auto) | AF5: Development action | AG5: Development due (auto) | AH5: QA (auto)
A6: =IF($B6="","","P"&TEXT(ROW()-5,"000")) | D6: =IF($C6="","",IFERROR(INDEX('1. Role Scoring'!$C$6:$C$255,MATCH($C6,'1. Role Scoring'!$B$6:$B$255,0)),"Role not in Step 1")) | E6: =IF($C6="","",IFERROR(INDEX('1. Role Scoring'!$D$6:$D$255,MATCH($C6,'1. Role Scoring'!$B$6:$B$255,0)),"")) | F6: =IF($C6="","",IFERROR(INDEX('1. Role Scoring'!$O$6:$O$255,MATCH($C6,'1. Role Scoring'!$B$6:$B$255,0)),"Role not in Step 1")) | L6: =IF($B6="","",IF($K6="","Needed",IF(TODAY()-$K6<=Setup!$B$15,"Current","Needed (>12 mo)"))) | O6: =IF($B6="","",IF($J6="","Reviews not entered",IF($J6=0,"Retrospective - extra probe","Reviews on record: "&$J6))) | S6: =IF(OR($P6="",$Q6="",$R6=""),"",IF(COUNTIF($P6:$R6,"Low")>0,"Low",IF(COUNTIF($P6:$R6,"High")=3,"High","Medium"))) | T6: =IF(OR($M6="",$S6=""),"",INDEX(Setup!$C$36:$E$38,4-$M6,MATCH($S6,Lists!$E$2:$E$4,0))) | U6: =IF($B6="","",IF(COUNTIF('3. Skills (SBJA)'!$A$6:$A$605,$B6)=0,"—",(COUNTIFS('3. Skills (SBJA)'!$A$6:$A$605,$B6,'3. Skills (SBJA)'!$F$6:$F$605,"At")+COUNTIFS('3. Skills (SBJA)'!$A$6:$A$605,$B6,'3. Skills (SBJA)'!$F$6:$F$605,"Above"))/COUNTIF('3. Skills (SBJA)'!$A$6:$A$605,$B6))) | V6: =IF($B6="","",IF(COUNTIF('3. Skills (SBJA)'!$A$6:$A$605,$B6)=0,"—",COUNTIFS('3. Skills (SBJA)'!$A$6:$A$605,$B6,'3. Skills (SBJA)'!$F$6:$F$605,"GAP"))) | Y6: =IF($B6="","",IF($W6="","Pending calibration",IF($W6="Support pathway - no label","Support pathway (no label)",IF($W6="Defer","Deferred",IF($W6="Override - documented",IF($X6="","⚠ Select override placement",$X6),IF($T6="","Pending assessment",$T6)))))) | AE6: =IF($B6="","",IF($F6<>"YES","n/a - not critical",IF(AND($H6<>"",$H6<6),"Deferred (<6 mo in role)",IF(OR($AA6="",$AB6="",$AD6=""),"Incomplete",IF(AND($AB6="Yes",$AC6=""),"Risk action missing","Complete"))))) | AG6: =IF(OR($B6="",Setup!$B$8=""),"",Setup!$B$8+30) | AH6: =IF($B6="","",_xlfn.TEXTJOIN(" · ",TRUE(),IF(AND($M6<>"",$N6=""),"⚠ Performance evidence missing",""),IF(AND($Q6<>"",$K6=""),"⚠ Aspiration needs a documented career conversation",""),IF(AND($M6<>"",$L6<>"Current"),"⚠ Career conversation needed",""),IF(AND($W6="Override - documented",$Z6=""),"⚠ Override rationale missing",""),IF(AND($AB6="Yes",$AC6=""),"⚠ Retention action missing",""),IF(AND($F6="YES",COUNTIF('3. Skills (SBJA)'!$A$6:$A$605,$B6)=0),"⚠ SBJA skills check missing (critical role)",""),IF(AND($I6="Yes",$W6<>"Support pathway - no label",$W6<>""),"⚠ Active performance process: support pathway, no label","")))
A7: =IF($B7="","","P"&TEXT(ROW()-5,"000")) | D7: =IF($C7="","",IFERROR(INDEX('1. Role Scoring'!$C$6:$C$255,MATCH($C7,'1. Role Scoring'!$B$6:$B$255,0)),"Role not in Step 1")) | E7: =IF($C7="","",IFERROR(INDEX('1. Role Scoring'!$D$6:$D$255,MATCH($C7,'1. Role Scoring'!$B$6:$B$255,0)),"")) | F7: =IF($C7="","",IFERROR(INDEX('1. Role Scoring'!$O$6:$O$255,MATCH($C7,'1. Role Scoring'!$B$6:$B$255,0)),"Role not in Step 1")) | L7: =IF($B7="","",IF($K7="","Needed",IF(TODAY()-$K7<=Setup!$B$15,"Current","Needed (>12 mo)"))) | O7: =IF($B7="","",IF($J7="","Reviews not entered",IF($J7=0,"Retrospective - extra probe","Reviews on record: "&$J7))) | S7: =IF(OR($P7="",$Q7="",$R7=""),"",IF(COUNTIF($P7:$R7,"Low")>0,"Low",IF(COUNTIF($P7:$R7,"High")=3,"High","Medium"))) | T7: =IF(OR($M7="",$S7=""),"",INDEX(Setup!$C$36:$E$38,4-$M7,MATCH($S7,Lists!$E$2:$E$4,0))) | U7: =IF($B7="","",IF(COUNTIF('3. Skills (SBJA)'!$A$6:$A$605,$B7)=0,"—",(COUNTIFS('3. Skills (SBJA)'!$A$6:$A$605,$B7,'3. Skills (SBJA)'!$F$6:$F$605,"At")+COUNTIFS('3. Skills (SBJA)'!$A$6:$A$605,$B7,'3. Skills (SBJA)'!$F$6:$F$605,"Above"))/COUNTIF('3. Skills (SBJA)'!$A$6:$A$605,$B7))) | V7: =IF($B7="","",IF(COUNTIF('3. Skills (SBJA)'!$A$6:$A$605,$B7)=0,"—",COUNTIFS('3. Skills (SBJA)'!$A$6:$A$605,$B7,'3. Skills (SBJA)'!$F$6:$F$605,"GAP"))) | Y7: =IF($B7="","",IF($W7="","Pending calibration",IF($W7="Support pathway - no label","Support pathway (no label)",IF($W7="Defer","Deferred",IF($W7="Override - documented",IF($X7="","⚠ Select override placement",$X7),IF($T7="","Pending assessment",$T7)))))) | AE7: =IF($B7="","",IF($F7<>"YES","n/a - not critical",IF(AND($H7<>"",$H7<6),"Deferred (<6 mo in role)",IF(OR($AA7="",$AB7="",$AD7=""),"Incomplete",IF(AND($AB7="Yes",$AC7=""),"Risk action missing","Complete"))))) | AG7: =IF(OR($B7="",Setup!$B$8=""),"",Setup!$B$8+30) | AH7: =IF($B7="","",_xlfn.TEXTJOIN(" · ",TRUE(),IF(AND($M7<>"",$N7=""),"⚠ Performance evidence missing",""),IF(AND($Q7<>"",$K7=""),"⚠ Aspiration needs a documented career conversation",""),IF(AND($M7<>"",$L7<>"Current"),"⚠ Career conversation needed",""),IF(AND($W7="Override - documented",$Z7=""),"⚠ Override rationale missing",""),IF(AND($AB7="Yes",$AC7=""),"⚠ Retention action missing",""),IF(AND($F7="YES",COUNTIF('3. Skills (SBJA)'!$A$6:$A$605,$B7)=0),"⚠ SBJA skills check missing (critical role)",""),IF(AND($I7="Yes",$W7<>"Support pathway - no label",$W7<>""),"⚠ Active performance process: support pathway, no label","")))
A8: =IF($B8="","","P"&TEXT(ROW()-5,"000")) | D8: =IF($C8="","",IFERROR(INDEX('1. Role Scoring'!$C$6:$C$255,MATCH($C8,'1. Role Scoring'!$B$6:$B$255,0)),"Role not in Step 1")) | E8: =IF($C8="","",IFERROR(INDEX('1. Role Scoring'!$D$6:$D$255,MATCH($C8,'1. Role Scoring'!$B$6:$B$255,0)),"")) | F8: =IF($C8="","",IFERROR(INDEX('1. Role Scoring'!$O$6:$O$255,MATCH($C8,'1. Role Scoring'!$B$6:$B$255,0)),"Role not in Step 1")) | L8: =IF($B8="","",IF($K8="","Needed",IF(TODAY()-$K8<=Setup!$B$15,"Current","Needed (>12 mo)"))) | O8: =IF($B8="","",IF($J8="","Reviews not entered",IF($J8=0,"Retrospective - extra probe","Reviews on record: "&$J8))) | S8: =IF(OR($P8="",$Q8="",$R8=""),"",IF(COUNTIF($P8:$R8,"Low")>0,"Low",IF(COUNTIF($P8:$R8,"High")=3,"High","Medium"))) | T8: =IF(OR($M8="",$S8=""),"",INDEX(Setup!$C$36:$E$38,4-$M8,MATCH($S8,Lists!$E$2:$E$4,0))) | U8: =IF($B8="","",IF(COUNTIF('3. Skills (SBJA)'!$A$6:$A$605,$B8)=0,"—",(COUNTIFS('3. Skills (SBJA)'!$A$6:$A$605,$B8,'3. Skills (SBJA)'!$F$6:$F$605,"At")+COUNTIFS('3. Skills (SBJA)'!$A$6:$A$605,$B8,'3. Skills (SBJA)'!$F$6:$F$605,"Above"))/COUNTIF('3. Skills (SBJA)'!$A$6:$A$605,$B8))) | V8: =IF($B8="","",IF(COUNTIF('3. Skills (SBJA)'!$A$6:$A$605,$B8)=0,"—",COUNTIFS('3. Skills (SBJA)'!$A$6:$A$605,$B8,'3. Skills (SBJA)'!$F$6:$F$605,"GAP"))) | Y8: =IF($B8="","",IF($W8="","Pending calibration",IF($W8="Support pathway - no label","Support pathway (no label)",IF($W8="Defer","Deferred",IF($W8="Override - documented",IF($X8="","⚠ Select override placement",$X8),IF($T8="","Pending assessment",$T8)))))) | AE8: =IF($B8="","",IF($F8<>"YES","n/a - not critical",IF(AND($H8<>"",$H8<6),"Deferred (<6 mo in role)",IF(OR($AA8="",$AB8="",$AD8=""),"Incomplete",IF(AND($AB8="Yes",$AC8=""),"Risk action missing","Complete"))))) | AG8: =IF(OR($B8="",Setup!$B$8=""),"",Setup!$B$8+30) | AH8: =IF($B8="","",_xlfn.TEXTJOIN(" · ",TRUE(),IF(AND($M8<>"",$N8=""),"⚠ Performance evidence missing",""),IF(AND($Q8<>"",$K8=""),"⚠ Aspiration needs a documented career conversation",""),IF(AND($M8<>"",$L8<>"Current"),"⚠ Career conversation needed",""),IF(AND($W8="Override - documented",$Z8=""),"⚠ Override rationale missing",""),IF(AND($AB8="Yes",$AC8=""),"⚠ Retention action missing",""),IF(AND($F8="YES",COUNTIF('3. Skills (SBJA)'!$A$6:$A$605,$B8)=0),"⚠ SBJA skills check missing (critical role)",""),IF(AND($I8="Yes",$W8<>"Support pathway - no label",$W8<>""),"⚠ Active performance process: support pathway, no label","")))
A9: =IF($B9="","","P"&TEXT(ROW()-5,"000")) | D9: =IF($C9="","",IFERROR(INDEX('1. Role Scoring'!$C$6:$C$255,MATCH($C9,'1. Role Scoring'!$B$6:$B$255,0)),"Role not in Step 1")) | E9: =IF($C9="","",IFERROR(INDEX('1. Role Scoring'!$D$6:$D$255,MATCH($C9,'1. Role Scoring'!$B$6:$B$255,0)),"")) | F9: =IF($C9="","",IFERROR(INDEX('1. Role Scoring'!$O$6:$O$255,MATCH($C9,'1. Role Scoring'!$B$6:$B$255,0)),"Role not in Step 1")) | L9: =IF($B9="","",IF($K9="","Needed",IF(TODAY()-$K9<=Setup!$B$15,"Current","Needed (>12 mo)"))) | O9: =IF($B9="","",IF($J9="","Reviews not entered",IF($J9=0,"Retrospective - extra probe","Reviews on record: "&$J9))) | S9: =IF(OR($P9="",$Q9="",$R9=""),"",IF(COUNTIF($P9:$R9,"Low")>0,"Low",IF(COUNTIF($P9:$R9,"High")=3,"High","Medium"))) | T9: =IF(OR($M9="",$S9=""),"",INDEX(Setup!$C$36:$E$38,4-$M9,MATCH($S9,Lists!$E$2:$E$4,0))) | U9: =IF($B9="","",IF(COUNTIF('3. Skills (SBJA)'!$A$6:$A$605,$B9)=0,"—",(COUNTIFS('3. Skills (SBJA)'!$A$6:$A$605,$B9,'3. Skills (SBJA)'!$F$6:$F$605,"At")+COUNTIFS('3. Skills (SBJA)'!$A$6:$A$605,$B9,'3. Skills (SBJA)'!$F$6:$F$605,"Above"))/COUNTIF('3. Skills (SBJA)'!$A$6:$A$605,$B9))) | V9: =IF($B9="","",IF(COUNTIF('3. Skills (SBJA)'!$A$6:$A$605,$B9)=0,"—",COUNTIFS('3. Skills (SBJA)'!$A$6:$A$605,$B9,'3. Skills (SBJA)'!$F$6:$F$605,"GAP"))) | Y9: =IF($B9="","",IF($W9="","Pending calibration",IF($W9="Support pathway - no label","Support pathway (no label)",IF($W9="Defer","Deferred",IF($W9="Override - documented",IF($X9="","⚠ Select override placement",$X9),IF($T9="","Pending assessment",$T9)))))) | AE9: =IF($B9="","",IF($F9<>"YES","n/a - not critical",IF(AND($H9<>"",$H9<6),"Deferred (<6 mo in role)",IF(OR($AA9="",$AB9="",$AD9=""),"Incomplete",IF(AND($AB9="Yes",$AC9=""),"Risk action missing","Complete"))))) | AG9: =IF(OR($B9="",Setup!$B$8=""),"",Setup!$B$8+30) | AH9: =IF($B9="","",_xlfn.TEXTJOIN(" · ",TRUE(),IF(AND($M9<>"",$N9=""),"⚠ Performance evidence missing",""),IF(AND($Q9<>"",$K9=""),"⚠ Aspiration needs a documented career conversation",""),IF(AND($M9<>"",$L9<>"Current"),"⚠ Career conversation needed",""),IF(AND($W9="Override - documented",$Z9=""),"⚠ Override rationale missing",""),IF(AND($AB9="Yes",$AC9=""),"⚠ Retention action missing",""),IF(AND($F9="YES",COUNTIF('3. Skills (SBJA)'!$A$6:$A$605,$B9)=0),"⚠ SBJA skills check missing (critical role)",""),IF(AND($I9="Yes",$W9<>"Support pathway - no label",$W9<>""),"⚠ Active performance process: support pathway, no label","")))
A10: =IF($B10="","","P"&TEXT(ROW()-5,"000")) | D10: =IF($C10="","",IFERROR(INDEX('1. Role Scoring'!$C$6:$C$255,MATCH($C10,'1. Role Scoring'!$B$6:$B$255,0)),"Role not in Step 1")) | E10: =IF($C10="","",IFERROR(INDEX('1. Role Scoring'!$D$6:$D$255,MATCH($C10,'1. Role Scoring'!$B$6:$B$255,0)),"")) | F10: =IF($C10="","",IFERROR(INDEX('1. Role Scoring'!$O$6:$O$255,MATCH($C10,'1. Role Scoring'!$B$6:$B$255,0)),"Role not in Step 1")) | L10: =IF($B10="","",IF($K10="","Needed",IF(TODAY()-$K10<=Setup!$B$15,"Current","Needed (>12 mo)"))) | O10: =IF($B10="","",IF($J10="","Reviews not entered",IF($J10=0,"Retrospective - extra probe","Reviews on record: "&$J10))) | S10: =IF(OR($P10="",$Q10="",$R10=""),"",IF(COUNTIF($P10:$R10,"Low")>0,"Low",IF(COUNTIF($P10:$R10,"High")=3,"High","Medium"))) | T10: =IF(OR($M10="",$S10=""),"",INDEX(Setup!$C$36:$E$38,4-$M10,MATCH($S10,Lists!$E$2:$E$4,0))) | U10: =IF($B10="","",IF(COUNTIF('3. Skills (SBJA)'!$A$6:$A$605,$B10)=0,"—",(COUNTIFS('3. Skills (SBJA)'!$A$6:$A$605,$B10,'3. Skills (SBJA)'!$F$6:$F$605,"At")+COUNTIFS('3. Skills (SBJA)'!$A$6:$A$605,$B10,'3. Skills (SBJA)'!$F$6:$F$605,"Above"))/COUNTIF('3. Skills (SBJA)'!$A$6:$A$605,$B10))) | V10: =IF($B10="","",IF(COUNTIF('3. Skills (SBJA)'!$A$6:$A$605,$B10)=0,"—",COUNTIFS('3. Skills (SBJA)'!$A$6:$A$605,$B10,'3. Skills (SBJA)'!$F$6:$F$605,"GAP"))) | Y10: =IF($B10="","",IF($W10="","Pending calibration",IF($W10="Support pathway - no label","Support pathway (no label)",IF($W10="Defer","Deferred",IF($W10="Override - documented",IF($X10="","⚠ Select override placement",$X10),IF($T10="","Pending assessment",$T10)))))) | AE10: =IF($B10="","",IF($F10<>"YES","n/a - not critical",IF(AND($H10<>"",$H10<6),"Deferred (<6 mo in role)",IF(OR($AA10="",$AB10="",$AD10=""),"Incomplete",IF(AND($AB10="Yes",$AC10=""),"Risk action missing","Complete"))))) | AG10: =IF(OR($B10="",Setup!$B$8=""),"",Setup!$B$8+30) | AH10: =IF($B10="","",_xlfn.TEXTJOIN(" · ",TRUE(),IF(AND($M10<>"",$N10=""),"⚠ Performance evidence missing",""),IF(AND($Q10<>"",$K10=""),"⚠ Aspiration needs a documented career conversation",""),IF(AND($M10<>"",$L10<>"Current"),"⚠ Career conversation needed",""),IF(AND($W10="Override - documented",$Z10=""),"⚠ Override rationale missing",""),IF(AND($AB10="Yes",$AC10=""),"⚠ Retention action missing",""),IF(AND($F10="YES",COUNTIF('3. Skills (SBJA)'!$A$6:$A$605,$B10)=0),"⚠ SBJA skills check missing (critical role)",""),IF(AND($I10="Yes",$W10<>"Support pathway - no label",$W10<>""),"⚠ Active performance process: support pathway, no label","")))
A11: =IF($B11="","","P"&TEXT(ROW()-5,"000")) | D11: =IF($C11="","",IFERROR(INDEX('1. Role Scoring'!$C$6:$C$255,MATCH($C11,'1. Role Scoring'!$B$6:$B$255,0)),"Role not in Step 1")) | E11: =IF($C11="","",IFERROR(INDEX('1. Role Scoring'!$D$6:$D$255,MATCH($C11,'1. Role Scoring'!$B$6:$B$255,0)),"")) | F11: =IF($C11="","",IFERROR(INDEX('1. Role Scoring'!$O$6:$O$255,MATCH($C11,'1. Role Scoring'!$B$6:$B$255,0)),"Role not in Step 1")) | L11: =IF($B11="","",IF($K11="","Needed",IF(TODAY()-$K11<=Setup!$B$15,"Current","Needed (>12 mo)"))) | O11: =IF($B11="","",IF($J11="","Reviews not entered",IF($J11=0,"Retrospective - extra probe","Reviews on record: "&$J11))) | S11: =IF(OR($P11="",$Q11="",$R11=""),"",IF(COUNTIF($P11:$R11,"Low")>0,"Low",IF(COUNTIF($P11:$R11,"High")=3,"High","Medium"))) | T11: =IF(OR($M11="",$S11=""),"",INDEX(Setup!$C$36:$E$38,4-$M11,MATCH($S11,Lists!$E$2:$E$4,0))) | U11: =IF($B11="","",IF(COUNTIF('3. Skills (SBJA)'!$A$6:$A$605,$B11)=0,"—",(COUNTIFS('3. Skills (SBJA)'!$A$6:$A$605,$B11,'3. Skills (SBJA)'!$F$6:$F$605,"At")+COUNTIFS('3. Skills (SBJA)'!$A$6:$A$605,$B11,'3. Skills (SBJA)'!$F$6:$F$605,"Above"))/COUNTIF('3. Skills (SBJA)'!$A$6:$A$605,$B11))) | V11: =IF($B11="","",IF(COUNTIF('3. Skills (SBJA)'!$A$6:$A$605,$B11)=0,"—",COUNTIFS('3. Skills (SBJA)'!$A$6:$A$605,$B11,'3. Skills (SBJA)'!$F$6:$F$605,"GAP"))) | Y11: =IF($B11="","",IF($W11="","Pending calibration",IF($W11="Support pathway - no label","Support pathway (no label)",IF($W11="Defer","Deferred",IF($W11="Override - documented",IF($X11="","⚠ Select override placement",$X11),IF($T11="","Pending assessment",$T11)))))) | AE11: =IF($B11="","",IF($F11<>"YES","n/a - not critical",IF(AND($H11<>"",$H11<6),"Deferred (<6 mo in role)",IF(OR($AA11="",$AB11="",$AD11=""),"Incomplete",IF(AND($AB11="Yes",$AC11=""),"Risk action missing","Complete"))))) | AG11: =IF(OR($B11="",Setup!$B$8=""),"",Setup!$B$8+30) | AH11: =IF($B11="","",_xlfn.TEXTJOIN(" · ",TRUE(),IF(AND($M11<>"",$N11=""),"⚠ Performance evidence missing",""),IF(AND($Q11<>"",$K11=""),"⚠ Aspiration needs a documented career conversation",""),IF(AND($M11<>"",$L11<>"Current"),"⚠ Career conversation needed",""),IF(AND($W11="Override - documented",$Z11=""),"⚠ Override rationale missing",""),IF(AND($AB11="Yes",$AC11=""),"⚠ Retention action missing",""),IF(AND($F11="YES",COUNTIF('3. Skills (SBJA)'!$A$6:$A$605,$B11)=0),"⚠ SBJA skills check missing (critical role)",""),IF(AND($I11="Yes",$W11<>"Support pathway - no label",$W11<>""),"⚠ Active performance process: support pathway, no label","")))
A12: =IF($B12="","","P"&TEXT(ROW()-5,"000")) | D12: =IF($C12="","",IFERROR(INDEX('1. Role Scoring'!$C$6:$C$255,MATCH($C12,'1. Role Scoring'!$B$6:$B$255,0)),"Role not in Step 1")) | E12: =IF($C12="","",IFERROR(INDEX('1. Role Scoring'!$D$6:$D$255,MATCH($C12,'1. Role Scoring'!$B$6:$B$255,0)),"")) | F12: =IF($C12="","",IFERROR(INDEX('1. Role Scoring'!$O$6:$O$255,MATCH($C12,'1. Role Scoring'!$B$6:$B$255,0)),"Role not in Step 1")) | L12: =IF($B12="","",IF($K12="","Needed",IF(TODAY()-$K12<=Setup!$B$15,"Current","Needed (>12 mo)"))) | O12: =IF($B12="","",IF($J12="","Reviews not entered",IF($J12=0,"Retrospective - extra probe","Reviews on record: "&$J12))) | S12: =IF(OR($P12="",$Q12="",$R12=""),"",IF(COUNTIF($P12:$R12,"Low")>0,"Low",IF(COUNTIF($P12:$R12,"High")=3,"High","Medium"))) | T12: =IF(OR($M12="",$S12=""),"",INDEX(Setup!$C$36:$E$38,4-$M12,MATCH($S12,Lists!$E$2:$E$4,0))) | U12: =IF($B12="","",IF(COUNTIF('3. Skills (SBJA)'!$A$6:$A$605,$B12)=0,"—",(COUNTIFS('3. Skills (SBJA)'!$A$6:$A$605,$B12,'3. Skills (SBJA)'!$F$6:$F$605,"At")+COUNTIFS('3. Skills (SBJA)'!$A$6:$A$605,$B12,'3. Skills (SBJA)'!$F$6:$F$605,"Above"))/COUNTIF('3. Skills (SBJA)'!$A$6:$A$605,$B12))) | V12: =IF($B12="","",IF(COUNTIF('3. Skills (SBJA)'!$A$6:$A$605,$B12)=0,"—",COUNTIFS('3. Skills (SBJA)'!$A$6:$A$605,$B12,'3. Skills (SBJA)'!$F$6:$F$605,"GAP"))) | Y12: =IF($B12="","",IF($W12="","Pending calibration",IF($W12="Support pathway - no label","Support pathway (no label)",IF($W12="Defer","Deferred",IF($W12="Override - documented",IF($X12="","⚠ Select override placement",$X12),IF($T12="","Pending assessment",$T12)))))) | AE12: =IF($B12="","",IF($F12<>"YES","n/a - not critical",IF(AND($H12<>"",$H12<6),"Deferred (<6 mo in role)",IF(OR($AA12="",$AB12="",$AD12=""),"Incomplete",IF(AND($AB12="Yes",$AC12=""),"Risk action missing","Complete"))))) | AG12: =IF(OR($B12="",Setup!$B$8=""),"",Setup!$B$8+30) | AH12: =IF($B12="","",_xlfn.TEXTJOIN(" · ",TRUE(),IF(AND($M12<>"",$N12=""),"⚠ Performance evidence missing",""),IF(AND($Q12<>"",$K12=""),"⚠ Aspiration needs a documented career conversation",""),IF(AND($M12<>"",$L12<>"Current"),"⚠ Career conversation needed",""),IF(AND($W12="Override - documented",$Z12=""),"⚠ Override rationale missing",""),IF(AND($AB12="Yes",$AC12=""),"⚠ Retention action missing",""),IF(AND($F12="YES",COUNTIF('3. Skills (SBJA)'!$A$6:$A$605,$B12)=0),"⚠ SBJA skills check missing (critical role)",""),IF(AND($I12="Yes",$W12<>"Support pathway - no label",$W12<>""),"⚠ Active performance process: support pathway, no label","")))
A13: =IF($B13="","","P"&TEXT(ROW()-5,"000")) | D13: =IF($C13="","",IFERROR(INDEX('1. Role Scoring'!$C$6:$C$255,MATCH($C13,'1. Role Scoring'!$B$6:$B$255,0)),"Role not in Step 1")) | E13: =IF($C13="","",IFERROR(INDEX('1. Role Scoring'!$D$6:$D$255,MATCH($C13,'1. Role Scoring'!$B$6:$B$255,0)),"")) | F13: =IF($C13="","",IFERROR(INDEX('1. Role Scoring'!$O$6:$O$255,MATCH($C13,'1. Role Scoring'!$B$6:$B$255,0)),"Role not in Step 1")) | L13: =IF($B13="","",IF($K13="","Needed",IF(TODAY()-$K13<=Setup!$B$15,"Current","Needed (>12 mo)"))) | O13: =IF($B13="","",IF($J13="","Reviews not entered",IF($J13=0,"Retrospective - extra probe","Reviews on record: "&$J13))) | S13: =IF(OR($P13="",$Q13="",$R13=""),"",IF(COUNTIF($P13:$R13,"Low")>0,"Low",IF(COUNTIF($P13:$R13,"High")=3,"High","Medium"))) | T13: =IF(OR($M13="",$S13=""),"",INDEX(Setup!$C$36:$E$38,4-$M13,MATCH($S13,Lists!$E$2:$E$4,0))) | U13: =IF($B13="","",IF(COUNTIF('3. Skills (SBJA)'!$A$6:$A$605,$B13)=0,"—",(COUNTIFS('3. Skills (SBJA)'!$A$6:$A$605,$B13,'3. Skills (SBJA)'!$F$6:$F$605,"At")+COUNTIFS('3. Skills (SBJA)'!$A$6:$A$605,$B13,'3. Skills (SBJA)'!$F$6:$F$605,"Above"))/COUNTIF('3. Skills (SBJA)'!$A$6:$A$605,$B13))) | V13: =IF($B13="","",IF(COUNTIF('3. Skills (SBJA)'!$A$6:$A$605,$B13)=0,"—",COUNTIFS('3. Skills (SBJA)'!$A$6:$A$605,$B13,'3. Skills (SBJA)'!$F$6:$F$605,"GAP"))) | Y13: =IF($B13="","",IF($W13="","Pending calibration",IF($W13="Support pathway - no label","Support pathway (no label)",IF($W13="Defer","Deferred",IF($W13="Override - documented",IF($X13="","⚠ Select override placement",$X13),IF($T13="","Pending assessment",$T13)))))) | AE13: =IF($B13="","",IF($F13<>"YES","n/a - not critical",IF(AND($H13<>"",$H13<6),"Deferred (<6 mo in role)",IF(OR($AA13="",$AB13="",$AD13=""),"Incomplete",IF(AND($AB13="Yes",$AC13=""),"Risk action missing","Complete"))))) | AG13: =IF(OR($B13="",Setup!$B$8=""),"",Setup!$B$8+30) | AH13: =IF($B13="","",_xlfn.TEXTJOIN(" · ",TRUE(),IF(AND($M13<>"",$N13=""),"⚠ Performance evidence missing",""),IF(AND($Q13<>"",$K13=""),"⚠ Aspiration needs a documented career conversation",""),IF(AND($M13<>"",$L13<>"Current"),"⚠ Career conversation needed",""),IF(AND($W13="Override - documented",$Z13=""),"⚠ Override rationale missing",""),IF(AND($AB13="Yes",$AC13=""),"⚠ Retention action missing",""),IF(AND($F13="YES",COUNTIF('3. Skills (SBJA)'!$A$6:$A$605,$B13)=0),"⚠ SBJA skills check missing (critical role)",""),IF(AND($I13="Yes",$W13<>"Support pathway - no label",$W13<>""),"⚠ Active performance process: support pathway, no label","")))
A14: =IF($B14="","","P"&TEXT(ROW()-5,"000")) | D14: =IF($C14="","",IFERROR(INDEX('1. Role Scoring'!$C$6:$C$255,MATCH($C14,'1. Role Scoring'!$B$6:$B$255,0)),"Role not in Step 1")) | E14: =IF($C14="","",IFERROR(INDEX('1. Role Scoring'!$D$6:$D$255,MATCH($C14,'1. Role Scoring'!$B$6:$B$255,0)),"")) | F14: =IF($C14="","",IFERROR(INDEX('1. Role Scoring'!$O$6:$O$255,MATCH($C14,'1. Role Scoring'!$B$6:$B$255,0)),"Role not in Step 1")) | L14: =IF($B14="","",IF($K14="","Needed",IF(TODAY()-$K14<=Setup!$B$15,"Current","Needed (>12 mo)"))) | O14: =IF($B14="","",IF($J14="","Reviews not entered",IF($J14=0,"Retrospective - extra probe","Reviews on record: "&$J14))) | S14: =IF(OR($P14="",$Q14="",$R14=""),"",IF(COUNTIF($P14:$R14,"Low")>0,"Low",IF(COUNTIF($P14:$R14,"High")=3,"High","Medium"))) | T14: =IF(OR($M14="",$S14=""),"",INDEX(Setup!$C$36:$E$38,4-$M14,MATCH($S14,Lists!$E$2:$E$4,0))) | U14: =IF($B14="","",IF(COUNTIF('3. Skills (SBJA)'!$A$6:$A$605,$B14)=0,"—",(COUNTIFS('3. Skills (SBJA)'!$A$6:$A$605,$B14,'3. Skills (SBJA)'!$F$6:$F$605,"At")+COUNTIFS('3. Skills (SBJA)'!$A$6:$A$605,$B14,'3. Skills (SBJA)'!$F$6:$F$605,"Above"))/COUNTIF('3. Skills (SBJA)'!$A$6:$A$605,$B14))) | V14: =IF($B14="","",IF(COUNTIF('3. Skills (SBJA)'!$A$6:$A$605,$B14)=0,"—",COUNTIFS('3. Skills (SBJA)'!$A$6:$A$605,$B14,'3. Skills (SBJA)'!$F$6:$F$605,"GAP"))) | Y14: =IF($B14="","",IF($W14="","Pending calibration",IF($W14="Support pathway - no label","Support pathway (no label)",IF($W14="Defer","Deferred",IF($W14="Override - documented",IF($X14="","⚠ Select override placement",$X14),IF($T14="","Pending assessment",$T14)))))) | AE14: =IF($B14="","",IF($F14<>"YES","n/a - not critical",IF(AND($H14<>"",$H14<6),"Deferred (<6 mo in role)",IF(OR($AA14="",$AB14="",$AD14=""),"Incomplete",IF(AND($AB14="Yes",$AC14=""),"Risk action missing","Complete"))))) | AG14: =IF(OR($B14="",Setup!$B$8=""),"",Setup!$B$8+30) | AH14: =IF($B14="","",_xlfn.TEXTJOIN(" · ",TRUE(),IF(AND($M14<>"",$N14=""),"⚠ Performance evidence missing",""),IF(AND($Q14<>"",$K14=""),"⚠ Aspiration needs a documented career conversation",""),IF(AND($M14<>"",$L14<>"Current"),"⚠ Career conversation needed",""),IF(AND($W14="Override - documented",$Z14=""),"⚠ Override rationale missing",""),IF(AND($AB14="Yes",$AC14=""),"⚠ Retention action missing",""),IF(AND($F14="YES",COUNTIF('3. Skills (SBJA)'!$A$6:$A$605,$B14)=0),"⚠ SBJA skills check missing (critical role)",""),IF(AND($I14="Yes",$W14<>"Support pathway - no label",$W14<>""),"⚠ Active performance process: support pathway, no label","")))
A15: =IF($B15="","","P"&TEXT(ROW()-5,"000")) | D15: =IF($C15="","",IFERROR(INDEX('1. Role Scoring'!$C$6:$C$255,MATCH($C15,'1. Role Scoring'!$B$6:$B$255,0)),"Role not in Step 1")) | E15: =IF($C15="","",IFERROR(INDEX('1. Role Scoring'!$D$6:$D$255,MATCH($C15,'1. Role Scoring'!$B$6:$B$255,0)),"")) | F15: =IF($C15="","",IFERROR(INDEX('1. Role Scoring'!$O$6:$O$255,MATCH($C15,'1. Role Scoring'!$B$6:$B$255,0)),"Role not in Step 1")) | L15: =IF($B15="","",IF($K15="","Needed",IF(TODAY()-$K15<=Setup!$B$15,"Current","Needed (>12 mo)"))) | O15: =IF($B15="","",IF($J15="","Reviews not entered",IF($J15=0,"Retrospective - extra probe","Reviews on record: "&$J15))) | S15: =IF(OR($P15="",$Q15="",$R15=""),"",IF(COUNTIF($P15:$R15,"Low")>0,"Low",IF(COUNTIF($P15:$R15,"High")=3,"High","Medium"))) | T15: =IF(OR($M15="",$S15=""),"",INDEX(Setup!$C$36:$E$38,4-$M15,MATCH($S15,Lists!$E$2:$E$4,0))) | U15: =IF($B15="","",IF(COUNTIF('3. Skills (SBJA)'!$A$6:$A$605,$B15)=0,"—",(COUNTIFS('3. Skills (SBJA)'!$A$6:$A$605,$B15,'3. Skills (SBJA)'!$F$6:$F$605,"At")+COUNTIFS('3. Skills (SBJA)'!$A$6:$A$605,$B15,'3. Skills (SBJA)'!$F$6:$F$605,"Above"))/COUNTIF('3. Skills (SBJA)'!$A$6:$A$605,$B15))) | V15: =IF($B15="","",IF(COUNTIF('3. Skills (SBJA)'!$A$6:$A$605,$B15)=0,"—",COUNTIFS('3. Skills (SBJA)'!$A$6:$A$605,$B15,'3. Skills (SBJA)'!$F$6:$F$605,"GAP"))) | Y15: =IF($B15="","",IF($W15="","Pending calibration",IF($W15="Support pathway - no label","Support pathway (no label)",IF($W15="Defer","Deferred",IF($W15="Override - documented",IF($X15="","⚠ Select override placement",$X15),IF($T15="","Pending assessment",$T15)))))) | AE15: =IF($B15="","",IF($F15<>"YES","n/a - not critical",IF(AND($H15<>"",$H15<6),"Deferred (<6 mo in role)",IF(OR($AA15="",$AB15="",$AD15=""),"Incomplete",IF(AND($AB15="Yes",$AC15=""),"Risk action missing","Complete"))))) | AG15: =IF(OR($B15="",Setup!$B$8=""),"",Setup!$B$8+30) | AH15: =IF($B15="","",_xlfn.TEXTJOIN(" · ",TRUE(),IF(AND($M15<>"",$N15=""),"⚠ Performance evidence missing",""),IF(AND($Q15<>"",$K15=""),"⚠ Aspiration needs a documented career conversation",""),IF(AND($M15<>"",$L15<>"Current"),"⚠ Career conversation needed",""),IF(AND($W15="Override - documented",$Z15=""),"⚠ Override rationale missing",""),IF(AND($AB15="Yes",$AC15=""),"⚠ Retention action missing",""),IF(AND($F15="YES",COUNTIF('3. Skills (SBJA)'!$A$6:$A$605,$B15)=0),"⚠ SBJA skills check missing (critical role)",""),IF(AND($I15="Yes",$W15<>"Support pathway - no label",$W15<>""),"⚠ Active performance process: support pathway, no label","")))
A16: =IF($B16="","","P"&TEXT(ROW()-5,"000")) | D16: =IF($C16="","",IFERROR(INDEX('1. Role Scoring'!$C$6:$C$255,MATCH($C16,'1. Role Scoring'!$B$6:$B$255,0)),"Role not in Step 1")) | E16: =IF($C16="","",IFERROR(INDEX('1. Role Scoring'!$D$6:$D$255,MATCH($C16,'1. Role Scoring'!$B$6:$B$255,0)),"")) | F16: =IF($C16="","",IFERROR(INDEX('1. Role Scoring'!$O$6:$O$255,MATCH($C16,'1. Role Scoring'!$B$6:$B$255,0)),"Role not in Step 1")) | L16: =IF($B16="","",IF($K16="","Needed",IF(TODAY()-$K16<=Setup!$B$15,"Current","Needed (>12 mo)"))) | O16: =IF($B16="","",IF($J16="","Reviews not entered",IF($J16=0,"Retrospective - extra probe","Reviews on record: "&$J16))) | S16: =IF(OR($P16="",$Q16="",$R16=""),"",IF(COUNTIF($P16:$R16,"Low")>0,"Low",IF(COUNTIF($P16:$R16,"High")=3,"High","Medium"))) | T16: =IF(OR($M16="",$S16=""),"",INDEX(Setup!$C$36:$E$38,4-$M16,MATCH($S16,Lists!$E$2:$E$4,0))) | U16: =IF($B16="","",IF(COUNTIF('3. Skills (SBJA)'!$A$6:$A$605,$B16)=0,"—",(COUNTIFS('3. Skills (SBJA)'!$A$6:$A$605,$B16,'3. Skills (SBJA)'!$F$6:$F$605,"At")+COUNTIFS('3. Skills (SBJA)'!$A$6:$A$605,$B16,'3. Skills (SBJA)'!$F$6:$F$605,"Above"))/COUNTIF('3. Skills (SBJA)'!$A$6:$A$605,$B16))) | V16: =IF($B16="","",IF(COUNTIF('3. Skills (SBJA)'!$A$6:$A$605,$B16)=0,"—",COUNTIFS('3. Skills (SBJA)'!$A$6:$A$605,$B16,'3. Skills (SBJA)'!$F$6:$F$605,"GAP"))) | Y16: =IF($B16="","",IF($W16="","Pending calibration",IF($W16="Support pathway - no label","Support pathway (no label)",IF($W16="Defer","Deferred",IF($W16="Override - documented",IF($X16="","⚠ Select override placement",$X16),IF($T16="","Pending assessment",$T16)))))) | AE16: =IF($B16="","",IF($F16<>"YES","n/a - not critical",IF(AND($H16<>"",$H16<6),"Deferred (<6 mo in role)",IF(OR($AA16="",$AB16="",$AD16=""),"Incomplete",IF(AND($AB16="Yes",$AC16=""),"Risk action missing","Complete"))))) | AG16: =IF(OR($B16="",Setup!$B$8=""),"",Setup!$B$8+30) | AH16: =IF($B16="","",_xlfn.TEXTJOIN(" · ",TRUE(),IF(AND($M16<>"",$N16=""),"⚠ Performance evidence missing",""),IF(AND($Q16<>"",$K16=""),"⚠ Aspiration needs a documented career conversation",""),IF(AND($M16<>"",$L16<>"Current"),"⚠ Career conversation needed",""),IF(AND($W16="Override - documented",$Z16=""),"⚠ Override rationale missing",""),IF(AND($AB16="Yes",$AC16=""),"⚠ Retention action missing",""),IF(AND($F16="YES",COUNTIF('3. Skills (SBJA)'!$A$6:$A$605,$B16)=0),"⚠ SBJA skills check missing (critical role)",""),IF(AND($I16="Yes",$W16<>"Support pathway - no label",$W16<>""),"⚠ Active performance process: support pathway, no label","")))
A17: =IF($B17="","","P"&TEXT(ROW()-5,"000")) | D17: =IF($C17="","",IFERROR(INDEX('1. Role Scoring'!$C$6:$C$255,MATCH($C17,'1. Role Scoring'!$B$6:$B$255,0)),"Role not in Step 1")) | E17: =IF($C17="","",IFERROR(INDEX('1. Role Scoring'!$D$6:$D$255,MATCH($C17,'1. Role Scoring'!$B$6:$B$255,0)),"")) | F17: =IF($C17="","",IFERROR(INDEX('1. Role Scoring'!$O$6:$O$255,MATCH($C17,'1. Role Scoring'!$B$6:$B$255,0)),"Role not in Step 1")) | L17: =IF($B17="","",IF($K17="","Needed",IF(TODAY()-$K17<=Setup!$B$15,"Current","Needed (>12 mo)"))) | O17: =IF($B17="","",IF($J17="","Reviews not entered",IF($J17=0,"Retrospective - extra probe","Reviews on record: "&$J17))) | S17: =IF(OR($P17="",$Q17="",$R17=""),"",IF(COUNTIF($P17:$R17,"Low")>0,"Low",IF(COUNTIF($P17:$R17,"High")=3,"High","Medium"))) | T17: =IF(OR($M17="",$S17=""),"",INDEX(Setup!$C$36:$E$38,4-$M17,MATCH($S17,Lists!$E$2:$E$4,0))) | U17: =IF($B17="","",IF(COUNTIF('3. Skills (SBJA)'!$A$6:$A$605,$B17)=0,"—",(COUNTIFS('3. Skills (SBJA)'!$A$6:$A$605,$B17,'3. Skills (SBJA)'!$F$6:$F$605,"At")+COUNTIFS('3. Skills (SBJA)'!$A$6:$A$605,$B17,'3. Skills (SBJA)'!$F$6:$F$605,"Above"))/COUNTIF('3. Skills (SBJA)'!$A$6:$A$605,$B17))) | V17: =IF($B17="","",IF(COUNTIF('3. Skills (SBJA)'!$A$6:$A$605,$B17)=0,"—",COUNTIFS('3. Skills (SBJA)'!$A$6:$A$605,$B17,'3. Skills (SBJA)'!$F$6:$F$605,"GAP"))) | Y17: =IF($B17="","",IF($W17="","Pending calibration",IF($W17="Support pathway - no label","Support pathway (no label)",IF($W17="Defer","Deferred",IF($W17="Override - documented",IF($X17="","⚠ Select override placement",$X17),IF($T17="","Pending assessment",$T17)))))) | AE17: =IF($B17="","",IF($F17<>"YES","n/a - not critical",IF(AND($H17<>"",$H17<6),"Deferred (<6 mo in role)",IF(OR($AA17="",$AB17="",$AD17=""),"Incomplete",IF(AND($AB17="Yes",$AC17=""),"Risk action missing","Complete"))))) | AG17: =IF(OR($B17="",Setup!$B$8=""),"",Setup!$B$8+30) | AH17: =IF($B17="","",_xlfn.TEXTJOIN(" · ",TRUE(),IF(AND($M17<>"",$N17=""),"⚠ Performance evidence missing",""),IF(AND($Q17<>"",$K17=""),"⚠ Aspiration needs a documented career conversation",""),IF(AND($M17<>"",$L17<>"Current"),"⚠ Career conversation needed",""),IF(AND($W17="Override - documented",$Z17=""),"⚠ Override rationale missing",""),IF(AND($AB17="Yes",$AC17=""),"⚠ Retention action missing",""),IF(AND($F17="YES",COUNTIF('3. Skills (SBJA)'!$A$6:$A$605,$B17)=0),"⚠ SBJA skills check missing (critical role)",""),IF(AND($I17="Yes",$W17<>"Support pathway - no label",$W17<>""),"⚠ Active performance process: support pathway, no label","")))
... A305: =IF($B305="","","P"&TEXT(ROW()-5,"000")) | D305: =IF($C305="","",IFERROR(INDEX('1. Role Scoring'!$C$6:$C$255,MATCH($C305,'1. Role Scoring'!$B$6:$B$255,0)),"Role not in Step 1")) | E305: =IF($C305="","",IFERROR(INDEX('1. Role Scoring'!$D$6:$D$255,MATCH($C305,'1. Role Scoring'!$B$6:$B$255,0)),"")) | F305: =IF($C305="","",IFERROR(INDEX('1. Role Scoring'!$O$6:$O$255,MATCH($C305,'1. Role Scoring'!$B$6:$B$255,0)),"Role not in Step 1")) | L305: =IF($B305="","",IF($K305="","Needed",IF(TODAY()-$K305<=Setup!$B$15,"Current","Needed (>12 mo)"))) | O305: =IF($B305="","",IF($J305="","Reviews not entered",IF($J305=0,"Retrospective - extra probe","Reviews on record: "&$J305))) | S305: =IF(OR($P305="",$Q305="",$R305=""),"",IF(COUNTIF($P305:$R305,"Low")>0,"Low",IF(COUNTIF($P305:$R305,"High")=3,"High","Medium"))) | T305: =IF(OR($M305="",$S305=""),"",INDEX(Setup!$C$36:$E$38,4-$M305,MATCH($S305,Lists!$E$2:$E$4,0))) | U305: =IF($B305="","",IF(COUNTIF('3. Skills (SBJA)'!$A$6:$A$605,$B305)=0,"—",(COUNTIFS('3. Skills (SBJA)'!$A$6:$A$605,$B305,'3. Skills (SBJA)'!$F$6:$F$605,"At")+COUNTIFS('3. Skills (SBJA)'!$A$6:$A$605,$B305,'3. Skills (SBJA)'!$F$6:$F$605,"Above"))/COUNTIF('3. Skills (SBJA)'!$A$6:$A$605,$B305))) | V305: =IF($B305="","",IF(COUNTIF('3. Skills (SBJA)'!$A$6:$A$605,$B305)=0,"—",COUNTIFS('3. Skills (SBJA)'!$A$6:$A$605,$B305,'3. Skills (SBJA)'!$F$6:$F$605,"GAP"))) | Y305: =IF($B305="","",IF($W305="","Pending calibration",IF($W305="Support pathway - no label","Support pathway (no label)",IF($W305="Defer","Deferred",IF($W305="Override - documented",IF($X305="","⚠ Select override placement",$X305),IF($T305="","Pending assessment",$T305)))))) | AE305: =IF($B305="","",IF($F305<>"YES","n/a - not critical",IF(AND($H305<>"",$H305<6),"Deferred (<6 mo in role)",IF(OR($AA305="",$AB305="",$AD305=""),"Incomplete",IF(AND($AB305="Yes",$AC305=""),"Risk action missing","Complete"))))) | AG305: =IF(OR($B305="",Setup!$B$8=""),"",Setup!$B$8+30) | AH305: =IF($B305="","",_xlfn.TEXTJOIN(" · ",TRUE(),IF(AND($M305<>"",$N305=""),"⚠ Performance evidence missing",""),IF(AND($Q305<>"",$K305=""),"⚠ Aspiration needs a documented career conversation",""),IF(AND($M305<>"",$L305<>"Current"),"⚠ Career conversation needed",""),IF(AND($W305="Override - documented",$Z305=""),"⚠ Override rationale missing",""),IF(AND($AB305="Yes",$AC305=""),"⚠ Retention action missing",""),IF(AND($F305="YES",COUNTIF('3. Skills (SBJA)'!$A$6:$A$605,$B305)=0),"⚠ SBJA skills check missing (critical role)",""),IF(AND($I305="Yes",$W305<>"Support pathway - no label",$W305<>""),"⚠ Active performance process: support pathway, no label","")))

Sheet 3. Skills (SBJA)
A1: SBJA Skills Check - critical roles only
A2: For each critical-role incumbent, list the skills the Skills-Based Job Architecture attaches to their role and the level the role requires, then rate the person's current level. One question: is this person at the level the role needs? At or above supports the placement; below becomes the development plan. Skills never decide a placement alone. The % at/above and gap count feed the Assessment tab automatically.
A5: Person (pick from Step 2) | B5: Role (auto) | C5: Skill (from the SBJA) | D5: Required @ role level | E5: Current level | F5: Δ (auto) | G5: Suggested action (auto)
B6: =IF($A6="","",IFERROR(INDEX('2. Assessment'!$C$6:$C$305,MATCH($A6,'2. Assessment'!$B$6:$B$305,0)),"Not in Step 2")) | F6: =IF(OR($A6="",$D6="",$E6=""),"",IF(MATCH($E6,Lists!$J$2:$J$5,0)>MATCH($D6,Lists!$J$2:$J$5,0),"Above",IF(MATCH($E6,Lists!$J$2:$J$5,0)=MATCH($D6,Lists!$J$2:$J$5,0),"At","GAP"))) | G6: =IF($F6="GAP","Development priority: "&$C6,IF($F6="Above","Capability evidence - feeds the ability discussion",""))
B7: =IF($A7="","",IFERROR(INDEX('2. Assessment'!$C$6:$C$305,MATCH($A7,'2. Assessment'!$B$6:$B$305,0)),"Not in Step 2")) | F7: =IF(OR($A7="",$D7="",$E7=""),"",IF(MATCH($E7,Lists!$J$2:$J$5,0)>MATCH($D7,Lists!$J$2:$J$5,0),"Above",IF(MATCH($E7,Lists!$J$2:$J$5,0)=MATCH($D7,Lists!$J$2:$J$5,0),"At","GAP"))) | G7: =IF($F7="GAP","Development priority: "&$C7,IF($F7="Above","Capability evidence - feeds the ability discussion",""))
B8: =IF($A8="","",IFERROR(INDEX('2. Assessment'!$C$6:$C$305,MATCH($A8,'2. Assessment'!$B$6:$B$305,0)),"Not in Step 2")) | F8: =IF(OR($A8="",$D8="",$E8=""),"",IF(MATCH($E8,Lists!$J$2:$J$5,0)>MATCH($D8,Lists!$J$2:$J$5,0),"Above",IF(MATCH($E8,Lists!$J$2:$J$5,0)=MATCH($D8,Lists!$J$2:$J$5,0),"At","GAP"))) | G8: =IF($F8="GAP","Development priority: "&$C8,IF($F8="Above","Capability evidence - feeds the ability discussion",""))
B9: =IF($A9="","",IFERROR(INDEX('2. Assessment'!$C$6:$C$305,MATCH($A9,'2. Assessment'!$B$6:$B$305,0)),"Not in Step 2")) | F9: =IF(OR($A9="",$D9="",$E9=""),"",IF(MATCH($E9,Lists!$J$2:$J$5,0)>MATCH($D9,Lists!$J$2:$J$5,0),"Above",IF(MATCH($E9,Lists!$J$2:$J$5,0)=MATCH($D9,Lists!$J$2:$J$5,0),"At","GAP"))) | G9: =IF($F9="GAP","Development priority: "&$C9,IF($F9="Above","Capability evidence - feeds the ability discussion",""))
B10: =IF($A10="","",IFERROR(INDEX('2. Assessment'!$C$6:$C$305,MATCH($A10,'2. Assessment'!$B$6:$B$305,0)),"Not in Step 2")) | F10: =IF(OR($A10="",$D10="",$E10=""),"",IF(MATCH($E10,Lists!$J$2:$J$5,0)>MATCH($D10,Lists!$J$2:$J$5,0),"Above",IF(MATCH($E10,Lists!$J$2:$J$5,0)=MATCH($D10,Lists!$J$2:$J$5,0),"At","GAP"))) | G10: =IF($F10="GAP","Development priority: "&$C10,IF($F10="Above","Capability evidence - feeds the ability discussion",""))
B11: =IF($A11="","",IFERROR(INDEX('2. Assessment'!$C$6:$C$305,MATCH($A11,'2. Assessment'!$B$6:$B$305,0)),"Not in Step 2")) | F11: =IF(OR($A11="",$D11="",$E11=""),"",IF(MATCH($E11,Lists!$J$2:$J$5,0)>MATCH($D11,Lists!$J$2:$J$5,0),"Above",IF(MATCH($E11,Lists!$J$2:$J$5,0)=MATCH($D11,Lists!$J$2:$J$5,0),"At","GAP"))) | G11: =IF($F11="GAP","Development priority: "&$C11,IF($F11="Above","Capability evidence - feeds the ability discussion",""))
B12: =IF($A12="","",IFERROR(INDEX('2. Assessment'!$C$6:$C$305,MATCH($A12,'2. Assessment'!$B$6:$B$305,0)),"Not in Step 2")) | F12: =IF(OR($A12="",$D12="",$E12=""),"",IF(MATCH($E12,Lists!$J$2:$J$5,0)>MATCH($D12,Lists!$J$2:$J$5,0),"Above",IF(MATCH($E12,Lists!$J$2:$J$5,0)=MATCH($D12,Lists!$J$2:$J$5,0),"At","GAP"))) | G12: =IF($F12="GAP","Development priority: "&$C12,IF($F12="Above","Capability evidence - feeds the ability discussion",""))
B13: =IF($A13="","",IFERROR(INDEX('2. Assessment'!$C$6:$C$305,MATCH($A13,'2. Assessment'!$B$6:$B$305,0)),"Not in Step 2")) | F13: =IF(OR($A13="",$D13="",$E13=""),"",IF(MATCH($E13,Lists!$J$2:$J$5,0)>MATCH($D13,Lists!$J$2:$J$5,0),"Above",IF(MATCH($E13,Lists!$J$2:$J$5,0)=MATCH($D13,Lists!$J$2:$J$5,0),"At","GAP"))) | G13: =IF($F13="GAP","Development priority: "&$C13,IF($F13="Above","Capability evidence - feeds the ability discussion",""))
B14: =IF($A14="","",IFERROR(INDEX('2. Assessment'!$C$6:$C$305,MATCH($A14,'2. Assessment'!$B$6:$B$305,0)),"Not in Step 2")) | F14: =IF(OR($A14="",$D14="",$E14=""),"",IF(MATCH($E14,Lists!$J$2:$J$5,0)>MATCH($D14,Lists!$J$2:$J$5,0),"Above",IF(MATCH($E14,Lists!$J$2:$J$5,0)=MATCH($D14,Lists!$J$2:$J$5,0),"At","GAP"))) | G14: =IF($F14="GAP","Development priority: "&$C14,IF($F14="Above","Capability evidence - feeds the ability discussion",""))
B15: =IF($A15="","",IFERROR(INDEX('2. Assessment'!$C$6:$C$305,MATCH($A15,'2. Assessment'!$B$6:$B$305,0)),"Not in Step 2")) | F15: =IF(OR($A15="",$D15="",$E15=""),"",IF(MATCH($E15,Lists!$J$2:$J$5,0)>MATCH($D15,Lists!$J$2:$J$5,0),"Above",IF(MATCH($E15,Lists!$J$2:$J$5,0)=MATCH($D15,Lists!$J$2:$J$5,0),"At","GAP"))) | G15: =IF($F15="GAP","Development priority: "&$C15,IF($F15="Above","Capability evidence - feeds the ability discussion",""))
